<?xml version="1.0" encoding="utf-8"?>
<!-- =================================================================================== -->
<!-- |    This document was autogenerated by xacro from orbo.urdf.xacro                | -->
<!-- |    EDITING THIS FILE BY HAND IS NOT RECOMMENDED                                 | -->
<!-- =================================================================================== -->
<robot name="robotis_op3">
  <!--
  <xacro:property name="pi" value="3.141592654" />
  -->
  <!-- right shoulder pitch joint 

  <xacro:macro name="insert_mesh_r_sho_pitch_link">
    <origin xyz="0 0 0" rpy="0 0 0" />
    <geometry>
      <mesh filename="package://op3_description/meshes/ra1.stl"  scale="0.001 0.001 0.001"/>
    </geometry>
    <material name="Grey">
      <color rgba="0.60 0.60 0.60 1.0"/>
    </material>
  </xacro:macro>

  -->
  <!-- right shoulder pitch joint 

  <xacro:macro name="insert_mesh_r_sho_roll_link">
    <origin xyz="0 0 0" rpy="0 0 0" />
    <geometry>
      <mesh filename="package://op3_description/meshes/ra2.stl"  scale="0.001 0.001 0.001"/>
    </geometry>
    <material name="Grey">
      <color rgba="0.60 0.60 0.60 1.0"/>
    </material>
  </xacro:macro>

  -->
  <!-- right elbow joint 

  <xacro:macro name="insert_mesh_r_el_link">
    <origin xyz="0 0 0" rpy="0 0 0" />
    <geometry>
      <mesh filename="package://op3_description/meshes/ra3.stl"  scale="0.001 0.001 0.001"/>
    </geometry>
    <material name="Grey">
      <color rgba="0.60 0.60 0.60 1.0"/>
    </material>
  </xacro:macro>
  
  -->
  <!-- left shoulder pitch joint 

  <xacro:macro name="insert_mesh_l_sho_pitch_link">
    <origin xyz="0 0 0" rpy="0 0 0" />
    <geometry>
      <mesh filename="package://op3_description/meshes/la1.stl"  scale="0.001 0.001 0.001"/>
    </geometry>
    <material name="Grey">
      <color rgba="0.60 0.60 0.60 1.0"/>
    </material>
  </xacro:macro>

  -->
  <!-- left shoulder pitch joint 

  <xacro:macro name="insert_mesh_l_sho_roll_link">
    <origin xyz="0 0 0" rpy="0 0 0" />
    <geometry>
      <mesh filename="package://op3_description/meshes/la2.stl"  scale="0.001 0.001 0.001"/>
    </geometry>
    <material name="Grey">
      <color rgba="0.60 0.60 0.60 1.0"/>
    </material>
  </xacro:macro>

  -->
  <!-- left elbow joint 

  <xacro:macro name="insert_mesh_l_el_link">
    <origin xyz="0 0 0" rpy="0 0 0" />
    <geometry>
      <mesh filename="package://op3_description/meshes/la3.stl"  scale="0.001 0.001 0.001"/>
    </geometry>
    <material name="Grey">
      <color rgba="0.60 0.60 0.60 1.0"/>
    </material>
  </xacro:macro>

  -->
  <!-- head yaw joint 

  <xacro:macro name="insert_mesh_head_pan_link">
    <origin xyz="0 0 0" rpy="0 0 0" />
    <geometry>
      <mesh filename="package://op3_description/meshes/h1.stl"  scale="0.001 0.001 0.001"/>
    </geometry>
    <material name="Grey">
      <color rgba="0.60 0.60 0.60 1.0"/>
    </material>
  </xacro:macro>

  -->
  <!-- head yaw joint 
  <xacro:macro name="insert_mesh_head_tilt_link">
    <origin xyz="0 0 0" rpy="0 0 0" />
    <geometry>
      <mesh filename="package://op3_description/meshes/h2.stl"  scale="0.001 0.001 0.001"/>
    </geometry>
    <material name="Grey">
      <color rgba="0.60 0.60 0.60 1.0"/>
    </material>
  </xacro:macro>

  -->
  <!-- right shoulder pitch joint 

  <xacro:macro name="insert_inertia_r_sho_pitch_link">
    <origin xyz="0.0 -0.00823 -0.00233" />
    <mass value="0.01176"/>
    <inertia ixx="0.00000165" ixy="0.0" ixz="0.0"
             iyy="0.00000387" iyz="-0.00000031"
             izz="0.00000397" />
  </xacro:macro>

  -->
  <!-- right shoulder roll joint 

  <xacro:macro name="insert_inertia_r_sho_roll_link">
    <origin xyz="-0.01844 -0.04514 0.00028" />
    <mass value="0.17758"/>
    <inertia ixx="0.00022804" ixy="0.00000001" ixz="0.00000003"
             iyy="0.00003042" iyz="-0.00000059"
             izz="0.00023474" />
  </xacro:macro>

  -->
  <!-- right elbow joint 

  <xacro:macro name="insert_inertia_r_el_link">
    <origin xyz="-0.01900 -0.07033 0.00380" />
    <mass value="0.04127"/>
    <inertia ixx="0.00006196" ixy="0.0" ixz="0.0"
             iyy="0.00001231" iyz="0.00000372"
             izz="0.00006854" />
  </xacro:macro>

  -->
  <!-- left shoulder pitch joint 

  <xacro:macro name="insert_inertia_l_sho_pitch_link">
    <origin xyz="0.0 0.00823 -0.00233" />
    <mass value="0.01176"/>
    <inertia ixx="0.00000165" ixy="0.0" ixz="0.0"
             iyy="0.00000387" iyz="0.00000031"
             izz="0.00000397" />
  </xacro:macro>

  -->
  <!-- left shoulder roll joint 

  <xacro:macro name="insert_inertia_l_sho_roll_link">
    <origin xyz="-0.01844 0.04514 0.00028" />
    <mass value="0.17758"/>
    <inertia ixx="0.00022804" ixy="-0.00000001" ixz="0.00000003"
             iyy="0.00003042" iyz="0.00000059"
             izz="0.00023474" />
  </xacro:macro>

  -->
  <!-- left elbow joint 

  <xacro:macro name="insert_inertia_l_el_link">
    <origin xyz="-0.01900 0.07033 0.00380" />
    <mass value="0.04127"/>
    <inertia ixx="0.00006196" ixy="0.0" ixz="0.0"
             iyy="0.00001231" iyz="-0.00000372"
             izz="0.00006854" />
  </xacro:macro>

  -->
  <!-- head yaw joint 

  <xacro:macro name="insert_inertia_head_pan_link">
    <origin xyz="0.00233 0.00000 0.00823" />
    <mass value="0.01176"/>
    <inertia ixx="0.00000397" ixy="0.0" ixz="-0.00000031"
             iyy="0.00000165" iyz="0.0"
             izz="0.00000387" />
  </xacro:macro>

  -->
  <!-- head pitch joint 
  <xacro:macro name="insert_inertia_head_tilt_link">
    <origin xyz="0.00230 -0.01863 0.02770" />
    <mass value="0.13631"/>
    <inertia ixx="0.00010612" ixy="0.00000011" ixz="-0.00000910"
             iyy="0.00008721" iyz="0.00000084"
             izz="0.00004529" />
  </xacro:macro>

  -->
  <!--
  <xacro:property name="pi" value="3.141592654" />
  -->
  <!--
  <xacro:property name="pi" value="3.141592654" />
  -->
  <!--
  <xacro:include filename="$(find op3_description)/urdf/robotis_op3.structure.rarm.xacro" />
  -->
  <!--
  <xacro:include filename="$(find op3_description)/urdf/robotis_op3.structure.larm.xacro" />
  -->
  <!--
  <xacro:include filename="$(find op3_description)/urdf/robotis_op3.structure.head.xacro" />
  -->
  <!--
  <xacro:include filename="$(find op3_description)/urdf/robotis_op3.gazebo.xacro" />
  -->
  <!--
  <xacro:include filename="$(find op3_description)/urdf/gazebo_harness.xacro" />
  -->
  <!-- harness link -->
  <!--
  <xacro:add_sim_harness harnessed_link="body_link"/>
  -->
  <!--
  <link name="world">
  </link>

  <joint name="world_fixed" type="fixed">
    <origin xyz="0 0 0" rpy="0 0 0"/>
    <parent link="world"/>
    <child link="base"/>
  </joint>

  <link name="base">
  </link>

  <joint name="base_fixed" type="fixed">
    <origin xyz="0 0 0" rpy="0 0 0"/>
    <parent link="base"/>
    <child link="body_link"/>
  </joint>
-->
  <!-- body link -->
  <link name="body_link">
    <visual>
      <origin rpy="0 0 0" xyz="0 0 0"/>
      <geometry>
        <mesh filename="package://op3_description/meshes/body.stl" scale="0.001 0.001 0.001"/>
      </geometry>
      <material name="Grey">
        <color rgba="0.60 0.60 0.60 1.0"/>
      </material>
    </visual>
    <collision>
      <origin rpy="0 0 0" xyz="0 0 0"/>
      <geometry>
        <mesh filename="package://op3_description/meshes/body.stl" scale="0.001 0.001 0.001"/>
      </geometry>
      <material name="Grey">
        <color rgba="0.60 0.60 0.60 1.0"/>
      </material>
    </collision>
    <inertial>
      <origin xyz="-0.01501 0.00013 0.06582"/>
      <mass value="1.34928"/>
      <inertia ixx="0.00340499" ixy="0.00000572" ixz="-0.00004256" iyy="0.00296939" iyz="-0.00000059" izz="0.00317331"/>
      <!--<inertia ixx="1.0" ixy="0.0" ixz="0.0" iyy="1.0" iyz="0.0" izz="1.0" />-->
    </inertial>
  </link>
  <!-- left hip yaw joint -->
  <joint name="l_hip_yaw" type="revolute">
    <parent link="body_link"/>
    <child link="l_hip_yaw_link"/>
    <origin rpy="0 0 0" xyz="0.0 0.035 0.0"/>
    <axis xyz="0 0 -1"/>
    <limit effort="1000" lower="-2.82743338823" upper="2.82743338823" velocity="100"/>
    <dynamics damping="0.1" friction="0.0"/>
  </joint>
  <transmission name="l_hip_yaw_tran">
    <type>transmission_interface/SimpleTransmission</type>
    <joint name="l_hip_yaw">
      <hardwareInterface>hardware_interface/EffortJointInterface</hardwareInterface>
    </joint>
    <actuator name="l_hip_yaw_motor">
      <hardwareInterface>hardware_interface/EffortJointInterface</hardwareInterface>
      <mechanicalReduction>1</mechanicalReduction>
    </actuator>
  </transmission>
  <!-- left hip yaw link -->
  <link name="l_hip_yaw_link">
    <visual>
      <origin rpy="0 0 0" xyz="0 0 0"/>
      <geometry>
        <mesh filename="package://op3_description/meshes/ll1.stl" scale="0.001 0.001 0.001"/>
      </geometry>
      <material name="Grey">
        <color rgba="0.60 0.60 0.60 1.0"/>
      </material>
    </visual>
    <collision>
      <origin rpy="0 0 0" xyz="0 0 0"/>
      <geometry>
        <mesh filename="package://op3_description/meshes/ll1.stl" scale="0.001 0.001 0.001"/>
      </geometry>
      <material name="Grey">
        <color rgba="0.60 0.60 0.60 1.0"/>
      </material>
    </collision>
    <inertial>
      <origin xyz="-0.00157 0.00000 -0.00774"/>
      <mass value="0.01181"/>
      <inertia ixx="0.00000151" ixy="0.0" ixz="0.00000001" iyy="0.00000430" iyz="0.0" izz="0.00000412"/>
    </inertial>
  </link>
  <!-- left hip roll joint -->
  <joint name="l_hip_roll" type="revolute">
    <parent link="l_hip_yaw_link"/>
    <child link="l_hip_roll_link"/>
    <origin rpy="0 0 0" xyz="-0.024 0.0 -0.0285"/>
    <axis xyz="-1 0 0"/>
    <limit effort="1000" lower="-2.82743338823" upper="2.82743338823" velocity="100"/>
    <dynamics damping="0.1" friction="0.0"/>
  </joint>
  <transmission name="l_hip_roll_tran">
    <type>transmission_interface/SimpleTransmission</type>
    <joint name="l_hip_roll">
      <hardwareInterface>hardware_interface/EffortJointInterface</hardwareInterface>
    </joint>
    <actuator name="l_hip_roll_motor">
      <hardwareInterface>hardware_interface/EffortJointInterface</hardwareInterface>
      <mechanicalReduction>1</mechanicalReduction>
    </actuator>
  </transmission>
  <!-- left hip roll link -->
  <link name="l_hip_roll_link">
    <visual>
      <origin rpy="0 0 0" xyz="0 0 0"/>
      <geometry>
        <mesh filename="package://op3_description/meshes/ll2.stl" scale="0.001 0.001 0.001"/>
      </geometry>
      <material name="Grey">
        <color rgba="0.60 0.60 0.60 1.0"/>
      </material>
    </visual>
    <collision>
      <origin rpy="0 0 0" xyz="0 0 0"/>
      <geometry>
        <mesh filename="package://op3_description/meshes/ll2.stl" scale="0.001 0.001 0.001"/>
      </geometry>
      <material name="Grey">
        <color rgba="0.60 0.60 0.60 1.0"/>
      </material>
    </collision>
    <inertial>
      <origin xyz="0.00388 0.00028 -0.01214"/>
      <mass value="0.17886"/>
      <inertia ixx="0.00004661" ixy="-0.00000101" ixz="-0.00000131" iyy="0.00012523" iyz="-0.00000006" izz="0.00010857"/>
    </inertial>
  </link>
  <!-- left hip pitch joint -->
  <joint name="l_hip_pitch" type="revolute">
    <parent link="l_hip_roll_link"/>
    <child link="l_hip_pitch_link"/>
    <origin rpy="0 0 0" xyz="0.0241 0.019 0.0"/>
    <axis xyz="0 1 0"/>
    <limit effort="1000" lower="-2.82743338823" upper="2.82743338823" velocity="100"/>
    <dynamics damping="0.1" friction="0.0"/>
  </joint>
  <transmission name="l_hip_pitch_tran">
    <type>transmission_interface/SimpleTransmission</type>
    <joint name="l_hip_pitch">
      <hardwareInterface>hardware_interface/EffortJointInterface</hardwareInterface>
    </joint>
    <actuator name="l_hip_pitch_motor">
      <hardwareInterface>hardware_interface/EffortJointInterface</hardwareInterface>
      <mechanicalReduction>1</mechanicalReduction>
    </actuator>
  </transmission>
  <!-- left hip pitch link -->
  <link name="l_hip_pitch_link">
    <visual>
      <origin rpy="0 0 0" xyz="0 0 0"/>
      <geometry>
        <mesh filename="package://op3_description/meshes/ll3.stl" scale="0.001 0.001 0.001"/>
      </geometry>
      <material name="Grey">
        <color rgba="0.60 0.60 0.60 1.0"/>
      </material>
    </visual>
    <collision>
      <origin rpy="0 0 0" xyz="0 0 0"/>
      <geometry>
        <mesh filename="package://op3_description/meshes/ll3.stl" scale="0.001 0.001 0.001"/>
      </geometry>
      <material name="Grey">
        <color rgba="0.60 0.60 0.60 1.0"/>
      </material>
    </collision>
    <inertial>
      <origin xyz="0.00059 -0.01901 -0.08408"/>
      <mass value="0.11543"/>
      <inertia ixx="0.00010499" ixy="-0.00000001" ixz="-0.00000071" iyy="0.00009613" iyz="0.00000353" izz="0.00002493"/>
    </inertial>
  </link>
  <!-- left knee joint -->
  <joint name="l_knee" type="revolute">
    <parent link="l_hip_pitch_link"/>
    <child link="l_knee_link"/>
    <origin rpy="0 0 0" xyz="0.0 0.0 -0.11015"/>
    <axis xyz="0 1 0"/>
    <limit effort="1000" lower="-2.82743338823" upper="2.82743338823" velocity="100"/>
    <dynamics damping="0.1" friction="0.0"/>
  </joint>
  <transmission name="l_knee_tran">
    <type>transmission_interface/SimpleTransmission</type>
    <joint name="l_knee">
      <hardwareInterface>hardware_interface/EffortJointInterface</hardwareInterface>
    </joint>
    <actuator name="l_knee_motor">
      <hardwareInterface>hardware_interface/EffortJointInterface</hardwareInterface>
      <mechanicalReduction>1</mechanicalReduction>
    </actuator>
  </transmission>
  <!-- left hip pitch link -->
  <link name="l_knee_link">
    <visual>
      <origin rpy="0 0 0" xyz="0 0 0"/>
      <geometry>
        <mesh filename="package://op3_description/meshes/ll4.stl" scale="0.001 0.001 0.001"/>
      </geometry>
      <material name="Grey">
        <color rgba="0.60 0.60 0.60 1.0"/>
      </material>
    </visual>
    <collision>
      <origin rpy="0 0 0" xyz="0 0 0"/>
      <geometry>
        <mesh filename="package://op3_description/meshes/ll4.stl" scale="0.001 0.001 0.001"/>
      </geometry>
      <material name="Grey">
        <color rgba="0.60 0.60 0.60 1.0"/>
      </material>
    </collision>
    <inertial>
      <origin xyz="0.00000 -0.02151 -0.05500"/>
      <mass value="0.04015"/>
      <inertia ixx="0.00003715" ixy="0.0" ixz="0.0" iyy="0.00002751" iyz="0.0" izz="0.00001511"/>
    </inertial>
  </link>
  <!-- left ankle pitch link -->
  <joint name="l_ank_pitch" type="revolute">
    <parent link="l_knee_link"/>
    <child link="l_ank_pitch_link"/>
    <origin rpy="0 0 0" xyz="0 0 -0.110"/>
    <axis xyz="0 -1 0"/>
    <limit effort="1000" lower="-2.82743338823" upper="2.82743338823" velocity="100"/>
    <dynamics damping="0.1" friction="0.0"/>
  </joint>
  <transmission name="l_ank_pitch_tran">
    <type>transmission_interface/SimpleTransmission</type>
    <joint name="l_ank_pitch">
      <hardwareInterface>hardware_interface/EffortJointInterface</hardwareInterface>
    </joint>
    <actuator name="l_ank_pitch_motor">
      <hardwareInterface>hardware_interface/EffortJointInterface</hardwareInterface>
      <mechanicalReduction>1</mechanicalReduction>
    </actuator>
  </transmission>
  <!-- left hip pitch link -->
  <link name="l_ank_pitch_link">
    <visual>
      <origin rpy="0 0 0" xyz="0 0 0"/>
      <geometry>
        <mesh filename="package://op3_description/meshes/ll5.stl" scale="0.001 0.001 0.001"/>
      </geometry>
      <material name="Grey">
        <color rgba="0.60 0.60 0.60 1.0"/>
      </material>
    </visual>
    <collision>
      <origin rpy="0 0 0" xyz="0 0 0"/>
      <geometry>
        <mesh filename="package://op3_description/meshes/ll5.stl" scale="0.001 0.001 0.001"/>
      </geometry>
      <material name="Grey">
        <color rgba="0.60 0.60 0.60 1.0"/>
      </material>
    </collision>
    <inertial>
      <origin xyz="-0.02022 -0.01872 0.01214"/>
      <mass value="0.17886"/>
      <inertia ixx="0.00004661" ixy="-0.00000101" ixz="0.00000131" iyy="0.00012523" iyz="0.00000006" izz="0.00010857"/>
    </inertial>
  </link>
  <!-- left ankle roll link -->
  <joint name="l_ank_roll" type="revolute">
    <parent link="l_ank_pitch_link"/>
    <child link="l_ank_roll_link"/>
    <origin rpy="0 0 0" xyz="-0.0241 -0.019 0"/>
    <axis xyz="1 0 0"/>
    <limit effort="1000" lower="-2.82743338823" upper="2.82743338823" velocity="100"/>
    <dynamics damping="0.1" friction="0.0"/>
  </joint>
  <transmission name="l_ank_roll_tran">
    <type>transmission_interface/SimpleTransmission</type>
    <joint name="l_ank_roll">
      <hardwareInterface>hardware_interface/EffortJointInterface</hardwareInterface>
    </joint>
    <actuator name="l_ank_roll_motor">
      <hardwareInterface>hardware_interface/EffortJointInterface</hardwareInterface>
      <mechanicalReduction>1</mechanicalReduction>
    </actuator>
  </transmission>
  <!-- left hip roll link -->
  <link name="l_ank_roll_link">
    <visual>
      <origin rpy="0 0 0" xyz="0 0 0"/>
      <geometry>
        <mesh filename="package://op3_description/meshes/ll6.stl" scale="0.001 0.001 0.001"/>
      </geometry>
      <material name="Grey">
        <color rgba="0.60 0.60 0.60 1.0"/>
      </material>
    </visual>
    <collision>
      <origin rpy="0 0 0" xyz="0 0 0"/>
      <geometry>
        <mesh filename="package://op3_description/meshes/ll6.stl" scale="0.001 0.001 0.001"/>
      </geometry>
      <material name="Grey">
        <color rgba="0.60 0.60 0.60 1.0"/>
      </material>
    </collision>
    <inertial>
      <origin xyz="0.02373 0.01037 -0.02760"/>
      <mass value="0.06934"/>
      <inertia ixx="0.00004034" ixy="-0.00000019" ixz="0.00000012" iyy="0.00007874" iyz="0.00000101" izz="0.00011579"/>
    </inertial>
  </link>
  <!-- right hip yaw joint -->
  <joint name="r_hip_yaw" type="revolute">
    <parent link="body_link"/>
    <child link="r_hip_yaw_link"/>
    <origin rpy="0 0 0" xyz="0.0 -0.035 0.0"/>
    <axis xyz="0 0 -1"/>
    <limit effort="1000" lower="-2.82743338823" upper="2.82743338823" velocity="100"/>
    <dynamics damping="0.1" friction="0.0"/>
  </joint>
  <transmission name="r_hip_yaw_tran">
    <type>transmission_interface/SimpleTransmission</type>
    <joint name="r_hip_yaw">
      <hardwareInterface>hardware_interface/EffortJointInterface</hardwareInterface>
    </joint>
    <actuator name="r_hip_yaw_motor">
      <hardwareInterface>hardware_interface/EffortJointInterface</hardwareInterface>
      <mechanicalReduction>1</mechanicalReduction>
    </actuator>
  </transmission>
  <!-- right hip yaw link -->
  <link name="r_hip_yaw_link">
    <visual>
      <origin rpy="0 0 0" xyz="0 0 0"/>
      <geometry>
        <mesh filename="package://op3_description/meshes/rl1.stl" scale="0.001 0.001 0.001"/>
      </geometry>
      <material name="Grey">
        <color rgba="0.60 0.60 0.60 1.0"/>
      </material>
    </visual>
    <collision>
      <origin rpy="0 0 0" xyz="0 0 0"/>
      <geometry>
        <mesh filename="package://op3_description/meshes/rl1.stl" scale="0.001 0.001 0.001"/>
      </geometry>
      <material name="Grey">
        <color rgba="0.60 0.60 0.60 1.0"/>
      </material>
    </collision>
    <inertial>
      <origin xyz="-0.00157 0.00000 -0.00774"/>
      <mass value="0.01181"/>
      <inertia ixx="0.00000151" ixy="0.0" ixz="0.00000001" iyy="0.00000430" iyz="0.0" izz="0.00000412"/>
    </inertial>
  </link>
  <!-- right hip roll joint -->
  <joint name="r_hip_roll" type="revolute">
    <parent link="r_hip_yaw_link"/>
    <child link="r_hip_roll_link"/>
    <origin rpy="0 0 0" xyz="-0.024 0.0 -0.0285"/>
    <axis xyz="-1 0 0"/>
    <limit effort="1000" lower="-2.82743338823" upper="2.82743338823" velocity="100"/>
    <dynamics damping="0.1" friction="0.0"/>
  </joint>
  <transmission name="r_hip_roll_tran">
    <type>transmission_interface/SimpleTransmission</type>
    <joint name="r_hip_roll">
      <hardwareInterface>hardware_interface/EffortJointInterface</hardwareInterface>
    </joint>
    <actuator name="r_hip_roll_motor">
      <hardwareInterface>hardware_interface/EffortJointInterface</hardwareInterface>
      <mechanicalReduction>1</mechanicalReduction>
    </actuator>
  </transmission>
  <!-- right hip roll link -->
  <link name="r_hip_roll_link">
    <visual>
      <origin rpy="0 0 0" xyz="0 0 0"/>
      <geometry>
        <mesh filename="package://op3_description/meshes/rl2.stl" scale="0.001 0.001 0.001"/>
      </geometry>
      <material name="Grey">
        <color rgba="0.60 0.60 0.60 1.0"/>
      </material>
    </visual>
    <collision>
      <origin rpy="0 0 0" xyz="0 0 0"/>
      <geometry>
        <mesh filename="package://op3_description/meshes/rl2.stl" scale="0.001 0.001 0.001"/>
      </geometry>
      <material name="Grey">
        <color rgba="0.60 0.60 0.60 1.0"/>
      </material>
    </collision>
    <inertial>
      <origin xyz="0.00388 -0.00028 -0.01214"/>
      <mass value="0.17886"/>
      <inertia ixx="0.00004661" ixy="0.00000101" ixz="-0.00000131" iyy="0.00012523" iyz="0.00000006" izz="0.00010857"/>
    </inertial>
  </link>
  <!-- right hip pitch joint -->
  <joint name="r_hip_pitch" type="revolute">
    <parent link="r_hip_roll_link"/>
    <child link="r_hip_pitch_link"/>
    <origin rpy="0 0 0" xyz="0.0241 -0.019 0.0"/>
    <axis xyz="0 -1 0"/>
    <limit effort="1000" lower="-2.82743338823" upper="2.82743338823" velocity="100"/>
    <dynamics damping="0.1" friction="0.0"/>
  </joint>
  <transmission name="r_hip_pitch_tran">
    <type>transmission_interface/SimpleTransmission</type>
    <joint name="r_hip_pitch">
      <hardwareInterface>hardware_interface/EffortJointInterface</hardwareInterface>
    </joint>
    <actuator name="r_hip_pitch_motor">
      <hardwareInterface>hardware_interface/EffortJointInterface</hardwareInterface>
      <mechanicalReduction>1</mechanicalReduction>
    </actuator>
  </transmission>
  <!-- right hip pitch link -->
  <link name="r_hip_pitch_link">
    <visual>
      <origin rpy="0 0 0" xyz="0 0 0"/>
      <geometry>
        <mesh filename="package://op3_description/meshes/rl3.stl" scale="0.001 0.001 0.001"/>
      </geometry>
      <material name="Grey">
        <color rgba="0.60 0.60 0.60 1.0"/>
      </material>
    </visual>
    <collision>
      <origin rpy="0 0 0" xyz="0 0 0"/>
      <geometry>
        <mesh filename="package://op3_description/meshes/rl3.stl" scale="0.001 0.001 0.001"/>
      </geometry>
      <material name="Grey">
        <color rgba="0.60 0.60 0.60 1.0"/>
      </material>
    </collision>
    <inertial>
      <origin xyz="0.00059 0.01901 -0.08408"/>
      <mass value="0.11543"/>
      <inertia ixx="0.00010499" ixy="0.00000001" ixz="-0.00000071" iyy="0.00009613" iyz="-0.00000353" izz="0.00002493"/>
    </inertial>
  </link>
  <!-- right knee joint -->
  <joint name="r_knee" type="revolute">
    <parent link="r_hip_pitch_link"/>
    <child link="r_knee_link"/>
    <origin rpy="0 0 0" xyz="0.0 0.0 -0.11015"/>
    <axis xyz="0 -1 0"/>
    <limit effort="1000" lower="-2.82743338823" upper="2.82743338823" velocity="100"/>
    <dynamics damping="0.1" friction="0.0"/>
  </joint>
  <transmission name="r_knee_tran">
    <type>transmission_interface/SimpleTransmission</type>
    <joint name="r_knee">
      <hardwareInterface>hardware_interface/EffortJointInterface</hardwareInterface>
    </joint>
    <actuator name="r_knee_motor">
      <hardwareInterface>hardware_interface/EffortJointInterface</hardwareInterface>
      <mechanicalReduction>1</mechanicalReduction>
    </actuator>
  </transmission>
  <!-- right hip pitch link -->
  <link name="r_knee_link">
    <visual>
      <origin rpy="0 0 0" xyz="0 0 0"/>
      <geometry>
        <mesh filename="package://op3_description/meshes/rl4.stl" scale="0.001 0.001 0.001"/>
      </geometry>
      <material name="Grey">
        <color rgba="0.60 0.60 0.60 1.0"/>
      </material>
    </visual>
    <collision>
      <origin rpy="0 0 0" xyz="0 0 0"/>
      <geometry>
        <mesh filename="package://op3_description/meshes/rl4.stl" scale="0.001 0.001 0.001"/>
      </geometry>
      <material name="Grey">
        <color rgba="0.60 0.60 0.60 1.0"/>
      </material>
    </collision>
    <inertial>
      <origin xyz="0.00000 0.02151 -0.05500"/>
      <mass value="0.04015"/>
      <inertia ixx="0.00003715" ixy="0.0" ixz="0.0" iyy="0.00002751" iyz="0.0" izz="0.00001511"/>
    </inertial>
  </link>
  <!-- right ankle pitch link -->
  <joint name="r_ank_pitch" type="revolute">
    <parent link="r_knee_link"/>
    <child link="r_ank_pitch_link"/>
    <origin rpy="0 0 0" xyz="0 0 -0.110"/>
    <axis xyz="0 1 0"/>
    <limit effort="1000" lower="-2.82743338823" upper="2.82743338823" velocity="100"/>
    <dynamics damping="0.1" friction="0.0"/>
  </joint>
  <transmission name="r_ank_pitch_tran">
    <type>transmission_interface/SimpleTransmission</type>
    <joint name="r_ank_pitch">
      <hardwareInterface>hardware_interface/EffortJointInterface</hardwareInterface>
    </joint>
    <actuator name="r_ank_pitch_motor">
      <hardwareInterface>hardware_interface/EffortJointInterface</hardwareInterface>
      <mechanicalReduction>1</mechanicalReduction>
    </actuator>
  </transmission>
  <!-- right hip pitch link -->
  <link name="r_ank_pitch_link">
    <visual>
      <origin rpy="0 0 0" xyz="0 0 0"/>
      <geometry>
        <mesh filename="package://op3_description/meshes/rl5.stl" scale="0.001 0.001 0.001"/>
      </geometry>
      <material name="Grey">
        <color rgba="0.60 0.60 0.60 1.0"/>
      </material>
    </visual>
    <collision>
      <origin rpy="0 0 0" xyz="0 0 0"/>
      <geometry>
        <mesh filename="package://op3_description/meshes/rl5.stl" scale="0.001 0.001 0.001"/>
      </geometry>
      <material name="Grey">
        <color rgba="0.60 0.60 0.60 1.0"/>
      </material>
    </collision>
    <inertial>
      <origin xyz="-0.02022 0.01872 0.01214"/>
      <mass value="0.17886"/>
      <inertia ixx="0.00004661" ixy="0.00000101" ixz="0.00000131" iyy="0.00012523" iyz="-0.00000006" izz="0.00010857"/>
    </inertial>
  </link>
  <!-- right ankle roll link -->
  <joint name="r_ank_roll" type="revolute">
    <parent link="r_ank_pitch_link"/>
    <child link="r_ank_roll_link"/>
    <origin rpy="0 0 0" xyz="-0.0241 0.019 0"/>
    <axis xyz="1 0 0"/>
    <limit effort="1000" lower="-2.82743338823" upper="2.82743338823" velocity="100"/>
    <dynamics damping="0.1" friction="0.0"/>
  </joint>
  <transmission name="r_ank_roll_tran">
    <type>transmission_interface/SimpleTransmission</type>
    <joint name="r_ank_roll">
      <hardwareInterface>hardware_interface/EffortJointInterface</hardwareInterface>
    </joint>
    <actuator name="r_ank_roll_motor">
      <hardwareInterface>hardware_interface/EffortJointInterface</hardwareInterface>
      <mechanicalReduction>1</mechanicalReduction>
    </actuator>
  </transmission>
  <!-- right hip roll link -->
  <link name="r_ank_roll_link">
    <visual>
      <origin rpy="0 0 0" xyz="0 0 0"/>
      <geometry>
        <mesh filename="package://op3_description/meshes/rl6.stl" scale="0.001 0.001 0.001"/>
      </geometry>
      <material name="Grey">
        <color rgba="0.60 0.60 0.60 1.0"/>
      </material>
    </visual>
    <collision>
      <origin rpy="0 0 0" xyz="0 0 0"/>
      <geometry>
        <mesh filename="package://op3_description/meshes/rl6.stl" scale="0.001 0.001 0.001"/>
      </geometry>
      <material name="Grey">
        <color rgba="0.60 0.60 0.60 1.0"/>
      </material>
    </collision>
    <inertial>
      <origin xyz="0.02373 -0.01037 -0.02760"/>
      <mass value="0.06934"/>
      <inertia ixx="0.00004034" ixy="0.00000019" ixz="0.00000012" iyy="0.00007874" iyz="-0.00000101" izz="0.00011579"/>
    </inertial>
  </link>
  <!-- arm link -->
  <!--
  <xacro:robotis_op3_l_arm parent="body_link" />
  -->
  <!--
  <xacro:robotis_op3_r_arm parent="body_link" />
  -->
  <!-- head links 
  <xacro:robotis_op3_head parent="body_link" />
  -->
</robot>

